<?xml version="1.0"?>
<robot xmlns:xacro="http://www.ros.org/wiki/xacro">

    <xacro:include filename="inertial_macros.xacro" />

    <xacro:property name="pi_const"         value="3.14159265359"/>
    <xacro:property name="wheel_separation" value="0.20"/>
    <xacro:property name="wheel_radius"     value="0.0325"/>
    <xacro:property name="wheel_thickness"  value="0.027"/>
    <xacro:property name="base_length"      value="0.30"/>
    <xacro:property name="base_width"       value="0.30"/>
    <xacro:property name="base_height"      value="0.08"/>
    <xacro:property name="lidar_x"          value="0.0"/>
    <xacro:property name="lidar_y"          value="0.0"/>
    <xacro:property name="lidar_z"          value="0.0975"/>
    <xacro:property name="lidar_radius"     value="0.05"/>
    <xacro:property name="lidar_thickness"  value="0.04"/>

    <material name="white"><color rgba="1 1 1 1"/></material>
    <material name="orange"><color rgba="1 0.3 0.1 1"/></material>
    <material name="blue"><color rgba="0.2 0.2 1 1"/></material>
    <material name="black"><color rgba="0 0 0 1"/></material>

    <link name="base_link"/>
    <link name="base_footprint"/>

    <joint name="base_footprint_joint" type="fixed">
        <parent link="base_footprint"/>
        <child link="base_link"/>
        <origin xyz="0 0 ${wheel_radius}" rpy="0 0 0"/>
    </joint>

    <joint name="chassis_joint" type="fixed">
        <parent link="base_link"/>
        <child link="chassis"/>
        <origin xyz="0 0 0" rpy="0 0 0"/>
    </joint>

    <link name="chassis">
        <visual>
            <origin xyz="0 0 ${base_height/2}" rpy="0 0 0"/>
            <geometry><box size="${base_length} ${base_width} ${base_height}"/></geometry>
            <material name="white"/>
        </visual>
        <collision>
            <origin xyz="0 0 ${base_height/2}" rpy="0 0 0"/>
            <geometry><box size="${base_length} ${base_width} ${base_height}"/></geometry>
        </collision>
        <xacro:inertial_box mass="0.5" x="${base_length}" y="${base_width}" z="${base_height}">
            <origin xyz="0 0 ${base_height/2}" rpy="0 0 0"/>
        </xacro:inertial_box>
    </link>

    <joint name="left_wheel_joint" type="continuous">
        <parent link="base_link"/>
        <child link="left_wheel"/>
        <origin xyz="0 ${wheel_separation/2} 0" rpy="-${pi_const/2} 0 0"/>
        <axis xyz="0 0 1"/>
    </joint>

    <link name="left_wheel">
        <visual>
            <geometry><cylinder length="${wheel_thickness}" radius="${wheel_radius}"/></geometry>
            <material name="blue"/>
        </visual>
        <collision>
            <geometry><cylinder length="${wheel_thickness}" radius="${wheel_radius}"/></geometry>
        </collision>
        <xacro:inertial_cylinder mass="0.1" length="${wheel_thickness}" radius="${wheel_radius}">
            <origin xyz="0 0 0" rpy="0 0 0"/>
        </xacro:inertial_cylinder>
    </link>

    <joint name="right_wheel_joint" type="continuous">
        <parent link="base_link"/>
        <child link="right_wheel"/>
        <origin xyz="0 -${wheel_separation/2} 0" rpy="${pi_const/2} 0 0"/>
        <axis xyz="0 0 1"/>
    </joint>

    <link name="right_wheel">
        <visual>
            <geometry><cylinder length="${wheel_thickness}" radius="${wheel_radius}"/></geometry>
            <material name="blue"/>
        </visual>
        <collision>
            <geometry><cylinder length="${wheel_thickness}" radius="${wheel_radius}"/></geometry>
        </collision>
        <xacro:inertial_cylinder mass="0.1" length="${wheel_thickness}" radius="${wheel_radius}">
            <origin xyz="0 0 0" rpy="0 0 0"/>
        </xacro:inertial_cylinder>
    </link>

    <joint name="lidar_joint" type="fixed">
        <parent link="base_link"/>
        <child link="laser_frame"/>
        <origin xyz="${lidar_x} ${lidar_y} ${lidar_z}" rpy="0 0 0"/>
    </joint>

    <link name="laser_frame">
        <visual>
            <geometry><cylinder length="${lidar_thickness}" radius="${lidar_radius}"/></geometry>
            <material name="black"/>
        </visual>
        <collision>
            <geometry><cylinder length="${lidar_thickness}" radius="${lidar_radius}"/></geometry>
        </collision>
        <xacro:inertial_cylinder mass="0.1" length="${lidar_thickness}" radius="${lidar_radius}">
            <origin xyz="0 0 0" rpy="0 0 0"/>
        </xacro:inertial_cylinder>
    </link>

</robot>
